<?xml version="1.0" encoding="UTF-8"?>
<testng-results skipped="0" failed="1" total="3" passed="2">
  <reporter-output>
  </reporter-output>
  <suite name="Suite" duration-ms="537224" started-at="2017-07-25T16:28:38Z" finished-at="2017-07-25T16:37:35Z">
    <groups>
    </groups>
    <test name="Test" duration-ms="537224" started-at="2017-07-25T16:28:38Z" finished-at="2017-07-25T16:37:35Z">
      <class name="com.flow.andriod.TC_Flowandriod_001">
        <test-method status="PASS" signature="TestValidation()[pri:0, instance:com.flow.andriod.TC_Flowandriod_001@1efed156]" test-instance-name="" name="TestValidation" duration-ms="220039" started-at="2017-07-25T21:58:38Z" finished-at="2017-07-25T22:02:18Z">
          <reporter-output>
          </reporter-output>
        </test-method> <!-- TestValidation -->
      </class> <!-- com.flow.andriod.TC_Flowandriod_001 -->
      <class name="com.flow.andriod.TC_Flowandriod_002">
        <test-method status="FAIL" signature="TestValidation()[pri:0, instance:com.flow.andriod.TC_Flowandriod_002@a7e666]" test-instance-name="" name="TestValidation" duration-ms="191242" started-at="2017-07-25T22:02:30Z" finished-at="2017-07-25T22:05:41Z">
          <exception class="java.lang.AssertionError">
            <message>
              <![CDATA[expected [true] but found [false]]]>
            </message>
            <full-stacktrace>
              <![CDATA[java.lang.AssertionError: expected [true] but found [false]
	at org.testng.Assert.fail(Assert.java:94)
	at org.testng.Assert.failNotEquals(Assert.java:513)
	at org.testng.Assert.assertTrue(Assert.java:42)
	at org.testng.Assert.assertTrue(Assert.java:52)
	at com.flow.andriod.TC_Flowandriod_002.TestValidation(TC_Flowandriod_002.java:63)
	at sun.reflect.NativeMethodAccessorImpl.invoke0(Native Method)
	at sun.reflect.NativeMethodAccessorImpl.invoke(Unknown Source)
	at sun.reflect.DelegatingMethodAccessorImpl.invoke(Unknown Source)
	at java.lang.reflect.Method.invoke(Unknown Source)
	at org.testng.internal.MethodInvocationHelper.invokeMethod(MethodInvocationHelper.java:86)
	at org.testng.internal.Invoker.invokeMethod(Invoker.java:643)
	at org.testng.internal.Invoker.invokeTestMethod(Invoker.java:820)
	at org.testng.internal.Invoker.invokeTestMethods(Invoker.java:1128)
	at org.testng.internal.TestMethodWorker.invokeTestMethods(TestMethodWorker.java:129)
	at org.testng.internal.TestMethodWorker.run(TestMethodWorker.java:112)
	at org.testng.TestRunner.privateRun(TestRunner.java:782)
	at org.testng.TestRunner.run(TestRunner.java:632)
	at org.testng.SuiteRunner.runTest(SuiteRunner.java:366)
	at org.testng.SuiteRunner.runSequentially(SuiteRunner.java:361)
	at org.testng.SuiteRunner.privateRun(SuiteRunner.java:319)
	at org.testng.SuiteRunner.run(SuiteRunner.java:268)
	at org.testng.SuiteRunnerWorker.runSuite(SuiteRunnerWorker.java:52)
	at org.testng.SuiteRunnerWorker.run(SuiteRunnerWorker.java:86)
	at org.testng.TestNG.runSuitesSequentially(TestNG.java:1244)
	at org.testng.TestNG.runSuitesLocally(TestNG.java:1169)
	at org.testng.TestNG.run(TestNG.java:1064)
	at org.testng.remote.AbstractRemoteTestNG.run(AbstractRemoteTestNG.java:132)
	at org.testng.remote.RemoteTestNG.initAndRun(RemoteTestNG.java:230)
	at org.testng.remote.RemoteTestNG.main(RemoteTestNG.java:76)
]]>
            </full-stacktrace>
          </exception> <!-- java.lang.AssertionError -->
          <reporter-output>
          </reporter-output>
        </test-method> <!-- TestValidation -->
      </class> <!-- com.flow.andriod.TC_Flowandriod_002 -->
      <class name="com.flow.andriod.TC_Flowandriod_003">
        <test-method status="PASS" signature="TestValidation()[pri:0, instance:com.flow.andriod.TC_Flowandriod_003@68bbe345]" test-instance-name="" name="TestValidation" duration-ms="96857" started-at="2017-07-25T22:05:50Z" finished-at="2017-07-25T22:07:27Z">
          <reporter-output>
          </reporter-output>
        </test-method> <!-- TestValidation -->
      </class> <!-- com.flow.andriod.TC_Flowandriod_003 -->
    </test> <!-- Test -->
  </suite> <!-- Suite -->
</testng-results>
